<?xml version="1.0" encoding="UTF-8"?>
<testng-results skipped="0" failed="9" total="10" passed="1">
  <reporter-output>
  </reporter-output>
  <suite name="Default suite" duration-ms="987" started-at="2017-07-17T21:34:10Z" finished-at="2017-07-17T21:34:11Z">
    <groups>
    </groups>
    <test name="Default test" duration-ms="987" started-at="2017-07-17T21:34:10Z" finished-at="2017-07-17T21:34:11Z">
      <class name="test.java.TstMultithreadServer">
        <test-method status="PASS" signature="beforeTest()[pri:0, instance:test.java.TstMultithreadServer@31a5c39e]" name="beforeTest" is-config="true" duration-ms="389" started-at="2017-07-18T00:34:10Z" finished-at="2017-07-18T00:34:11Z">
          <reporter-output>
          </reporter-output>
        </test-method> <!-- beforeTest -->
        <test-method status="PASS" signature="scenario1(java.util.List, java.util.List)[pri:0, instance:test.java.TstMultithreadServer@31a5c39e]" name="scenario1" duration-ms="83" started-at="2017-07-18T00:34:11Z" data-provider="scenario1" finished-at="2017-07-18T00:34:11Z">
          <params>
            <param index="0">
              <value>
                <![CDATA[[command=sign_in&login=Anton&password=passWord4, command=ban_user&login=Petr&signIn=BAN, command=edit_access&login=Sema&access=U, command=sign_out&login=Anton]]]>
              </value>
            </param>
            <param index="1">
              <value>
                <![CDATA[[Welcom!, Profile is changed!, Access is changed!, Good Bye!]]]>
              </value>
            </param>
          </params>
          <reporter-output>
          </reporter-output>
        </test-method> <!-- scenario1 -->
        <test-method status="FAIL" signature="scenario1(java.util.List, java.util.List)[pri:0, instance:test.java.TstMultithreadServer@31a5c39e]" name="scenario1" duration-ms="32" started-at="2017-07-18T00:34:11Z" data-provider="scenario1" finished-at="2017-07-18T00:34:11Z">
          <params>
            <param index="0">
              <value>
                <![CDATA[[command=sign_in&login=Anton&password=passWord4, command=ban_user&login=Petr&signIn=BAN, command=edit_access&login=Sema&access=U, command=sign_out&login=Anton]]]>
              </value>
            </param>
            <param index="1">
              <value>
                <![CDATA[[Welcom!, Profile is changed!, Access is changed!, Good Bye!]]]>
              </value>
            </param>
          </params>
          <exception class="java.lang.AssertionError">
            <message>
              <![CDATA[expected [Profile is changed!] but found [User already BAN!]]]>
            </message>
            <full-stacktrace>
              <![CDATA[java.lang.AssertionError: expected [Profile is changed!] but found [User already BAN!]
	at org.testng.Assert.fail(Assert.java:94)
	at org.testng.Assert.failNotEquals(Assert.java:513)
	at org.testng.Assert.assertEqualsImpl(Assert.java:135)
	at org.testng.Assert.assertEquals(Assert.java:116)
	at org.testng.Assert.assertEquals(Assert.java:190)
	at org.testng.Assert.assertEquals(Assert.java:200)
	at test.java.TstMultithreadServer.scenario1(TstMultithreadServer.java:45)
	at sun.reflect.NativeMethodAccessorImpl.invoke0(Native Method)
	at sun.reflect.NativeMethodAccessorImpl.invoke(Unknown Source)
	at sun.reflect.DelegatingMethodAccessorImpl.invoke(Unknown Source)
	at java.lang.reflect.Method.invoke(Unknown Source)
	at org.testng.internal.MethodInvocationHelper.invokeMethod(MethodInvocationHelper.java:100)
	at org.testng.internal.InvokeMethodRunnable.runOne(InvokeMethodRunnable.java:54)
	at org.testng.internal.InvokeMethodRunnable.run(InvokeMethodRunnable.java:44)
	at java.util.concurrent.Executors$RunnableAdapter.call(Unknown Source)
	at java.util.concurrent.FutureTask.run(Unknown Source)
	at java.util.concurrent.ThreadPoolExecutor.runWorker(Unknown Source)
	at java.util.concurrent.ThreadPoolExecutor$Worker.run(Unknown Source)
	at java.lang.Thread.run(Unknown Source)
]]>
            </full-stacktrace>
          </exception> <!-- java.lang.AssertionError -->
          <reporter-output>
          </reporter-output>
        </test-method> <!-- scenario1 -->
        <test-method status="FAIL" signature="scenario1(java.util.List, java.util.List)[pri:0, instance:test.java.TstMultithreadServer@31a5c39e]" name="scenario1" duration-ms="36" started-at="2017-07-18T00:34:11Z" data-provider="scenario1" finished-at="2017-07-18T00:34:11Z">
          <params>
            <param index="0">
              <value>
                <![CDATA[[command=sign_in&login=Anton&password=passWord4, command=ban_user&login=Petr&signIn=BAN, command=edit_access&login=Sema&access=U, command=sign_out&login=Anton]]]>
              </value>
            </param>
            <param index="1">
              <value>
                <![CDATA[[Welcom!, Profile is changed!, Access is changed!, Good Bye!]]]>
              </value>
            </param>
          </params>
          <exception class="java.lang.AssertionError">
            <message>
              <![CDATA[expected [Profile is changed!] but found [User already BAN!]]]>
            </message>
            <full-stacktrace>
              <![CDATA[java.lang.AssertionError: expected [Profile is changed!] but found [User already BAN!]
	at org.testng.Assert.fail(Assert.java:94)
	at org.testng.Assert.failNotEquals(Assert.java:513)
	at org.testng.Assert.assertEqualsImpl(Assert.java:135)
	at org.testng.Assert.assertEquals(Assert.java:116)
	at org.testng.Assert.assertEquals(Assert.java:190)
	at org.testng.Assert.assertEquals(Assert.java:200)
	at test.java.TstMultithreadServer.scenario1(TstMultithreadServer.java:45)
	at sun.reflect.NativeMethodAccessorImpl.invoke0(Native Method)
	at sun.reflect.NativeMethodAccessorImpl.invoke(Unknown Source)
	at sun.reflect.DelegatingMethodAccessorImpl.invoke(Unknown Source)
	at java.lang.reflect.Method.invoke(Unknown Source)
	at org.testng.internal.MethodInvocationHelper.invokeMethod(MethodInvocationHelper.java:100)
	at org.testng.internal.InvokeMethodRunnable.runOne(InvokeMethodRunnable.java:54)
	at org.testng.internal.InvokeMethodRunnable.run(InvokeMethodRunnable.java:44)
	at java.util.concurrent.Executors$RunnableAdapter.call(Unknown Source)
	at java.util.concurrent.FutureTask.run(Unknown Source)
	at java.util.concurrent.ThreadPoolExecutor.runWorker(Unknown Source)
	at java.util.concurrent.ThreadPoolExecutor$Worker.run(Unknown Source)
	at java.lang.Thread.run(Unknown Source)
]]>
            </full-stacktrace>
          </exception> <!-- java.lang.AssertionError -->
          <reporter-output>
          </reporter-output>
        </test-method> <!-- scenario1 -->
        <test-method status="FAIL" signature="scenario1(java.util.List, java.util.List)[pri:0, instance:test.java.TstMultithreadServer@31a5c39e]" name="scenario1" duration-ms="29" started-at="2017-07-18T00:34:11Z" data-provider="scenario1" finished-at="2017-07-18T00:34:11Z">
          <params>
            <param index="0">
              <value>
                <![CDATA[[command=sign_in&login=Anton&password=passWord4, command=ban_user&login=Petr&signIn=BAN, command=edit_access&login=Sema&access=U, command=sign_out&login=Anton]]]>
              </value>
            </param>
            <param index="1">
              <value>
                <![CDATA[[Welcom!, Profile is changed!, Access is changed!, Good Bye!]]]>
              </value>
            </param>
          </params>
          <exception class="java.lang.AssertionError">
            <message>
              <![CDATA[expected [Profile is changed!] but found [User already BAN!]]]>
            </message>
            <full-stacktrace>
              <![CDATA[java.lang.AssertionError: expected [Profile is changed!] but found [User already BAN!]
	at org.testng.Assert.fail(Assert.java:94)
	at org.testng.Assert.failNotEquals(Assert.java:513)
	at org.testng.Assert.assertEqualsImpl(Assert.java:135)
	at org.testng.Assert.assertEquals(Assert.java:116)
	at org.testng.Assert.assertEquals(Assert.java:190)
	at org.testng.Assert.assertEquals(Assert.java:200)
	at test.java.TstMultithreadServer.scenario1(TstMultithreadServer.java:45)
	at sun.reflect.NativeMethodAccessorImpl.invoke0(Native Method)
	at sun.reflect.NativeMethodAccessorImpl.invoke(Unknown Source)
	at sun.reflect.DelegatingMethodAccessorImpl.invoke(Unknown Source)
	at java.lang.reflect.Method.invoke(Unknown Source)
	at org.testng.internal.MethodInvocationHelper.invokeMethod(MethodInvocationHelper.java:100)
	at org.testng.internal.InvokeMethodRunnable.runOne(InvokeMethodRunnable.java:54)
	at org.testng.internal.InvokeMethodRunnable.run(InvokeMethodRunnable.java:44)
	at java.util.concurrent.Executors$RunnableAdapter.call(Unknown Source)
	at java.util.concurrent.FutureTask.run(Unknown Source)
	at java.util.concurrent.ThreadPoolExecutor.runWorker(Unknown Source)
	at java.util.concurrent.ThreadPoolExecutor$Worker.run(Unknown Source)
	at java.lang.Thread.run(Unknown Source)
]]>
            </full-stacktrace>
          </exception> <!-- java.lang.AssertionError -->
          <reporter-output>
          </reporter-output>
        </test-method> <!-- scenario1 -->
        <test-method status="FAIL" signature="scenario1(java.util.List, java.util.List)[pri:0, instance:test.java.TstMultithreadServer@31a5c39e]" name="scenario1" duration-ms="31" started-at="2017-07-18T00:34:11Z" data-provider="scenario1" finished-at="2017-07-18T00:34:11Z">
          <params>
            <param index="0">
              <value>
                <![CDATA[[command=sign_in&login=Anton&password=passWord4, command=ban_user&login=Petr&signIn=BAN, command=edit_access&login=Sema&access=U, command=sign_out&login=Anton]]]>
              </value>
            </param>
            <param index="1">
              <value>
                <![CDATA[[Welcom!, Profile is changed!, Access is changed!, Good Bye!]]]>
              </value>
            </param>
          </params>
          <exception class="java.lang.AssertionError">
            <message>
              <![CDATA[expected [Profile is changed!] but found [User already BAN!]]]>
            </message>
            <full-stacktrace>
              <![CDATA[java.lang.AssertionError: expected [Profile is changed!] but found [User already BAN!]
	at org.testng.Assert.fail(Assert.java:94)
	at org.testng.Assert.failNotEquals(Assert.java:513)
	at org.testng.Assert.assertEqualsImpl(Assert.java:135)
	at org.testng.Assert.assertEquals(Assert.java:116)
	at org.testng.Assert.assertEquals(Assert.java:190)
	at org.testng.Assert.assertEquals(Assert.java:200)
	at test.java.TstMultithreadServer.scenario1(TstMultithreadServer.java:45)
	at sun.reflect.NativeMethodAccessorImpl.invoke0(Native Method)
	at sun.reflect.NativeMethodAccessorImpl.invoke(Unknown Source)
	at sun.reflect.DelegatingMethodAccessorImpl.invoke(Unknown Source)
	at java.lang.reflect.Method.invoke(Unknown Source)
	at org.testng.internal.MethodInvocationHelper.invokeMethod(MethodInvocationHelper.java:100)
	at org.testng.internal.InvokeMethodRunnable.runOne(InvokeMethodRunnable.java:54)
	at org.testng.internal.InvokeMethodRunnable.run(InvokeMethodRunnable.java:44)
	at java.util.concurrent.Executors$RunnableAdapter.call(Unknown Source)
	at java.util.concurrent.FutureTask.run(Unknown Source)
	at java.util.concurrent.ThreadPoolExecutor.runWorker(Unknown Source)
	at java.util.concurrent.ThreadPoolExecutor$Worker.run(Unknown Source)
	at java.lang.Thread.run(Unknown Source)
]]>
            </full-stacktrace>
          </exception> <!-- java.lang.AssertionError -->
          <reporter-output>
          </reporter-output>
        </test-method> <!-- scenario1 -->
        <test-method status="FAIL" signature="scenario1(java.util.List, java.util.List)[pri:0, instance:test.java.TstMultithreadServer@31a5c39e]" name="scenario1" duration-ms="27" started-at="2017-07-18T00:34:11Z" data-provider="scenario1" finished-at="2017-07-18T00:34:11Z">
          <params>
            <param index="0">
              <value>
                <![CDATA[[command=sign_in&login=Anton&password=passWord4, command=ban_user&login=Petr&signIn=BAN, command=edit_access&login=Sema&access=U, command=sign_out&login=Anton]]]>
              </value>
            </param>
            <param index="1">
              <value>
                <![CDATA[[Welcom!, Profile is changed!, Access is changed!, Good Bye!]]]>
              </value>
            </param>
          </params>
          <exception class="java.lang.AssertionError">
            <message>
              <![CDATA[expected [Profile is changed!] but found [User already BAN!]]]>
            </message>
            <full-stacktrace>
              <![CDATA[java.lang.AssertionError: expected [Profile is changed!] but found [User already BAN!]
	at org.testng.Assert.fail(Assert.java:94)
	at org.testng.Assert.failNotEquals(Assert.java:513)
	at org.testng.Assert.assertEqualsImpl(Assert.java:135)
	at org.testng.Assert.assertEquals(Assert.java:116)
	at org.testng.Assert.assertEquals(Assert.java:190)
	at org.testng.Assert.assertEquals(Assert.java:200)
	at test.java.TstMultithreadServer.scenario1(TstMultithreadServer.java:45)
	at sun.reflect.NativeMethodAccessorImpl.invoke0(Native Method)
	at sun.reflect.NativeMethodAccessorImpl.invoke(Unknown Source)
	at sun.reflect.DelegatingMethodAccessorImpl.invoke(Unknown Source)
	at java.lang.reflect.Method.invoke(Unknown Source)
	at org.testng.internal.MethodInvocationHelper.invokeMethod(MethodInvocationHelper.java:100)
	at org.testng.internal.InvokeMethodRunnable.runOne(InvokeMethodRunnable.java:54)
	at org.testng.internal.InvokeMethodRunnable.run(InvokeMethodRunnable.java:44)
	at java.util.concurrent.Executors$RunnableAdapter.call(Unknown Source)
	at java.util.concurrent.FutureTask.run(Unknown Source)
	at java.util.concurrent.ThreadPoolExecutor.runWorker(Unknown Source)
	at java.util.concurrent.ThreadPoolExecutor$Worker.run(Unknown Source)
	at java.lang.Thread.run(Unknown Source)
]]>
            </full-stacktrace>
          </exception> <!-- java.lang.AssertionError -->
          <reporter-output>
          </reporter-output>
        </test-method> <!-- scenario1 -->
        <test-method status="FAIL" signature="scenario1(java.util.List, java.util.List)[pri:0, instance:test.java.TstMultithreadServer@31a5c39e]" name="scenario1" duration-ms="35" started-at="2017-07-18T00:34:11Z" data-provider="scenario1" finished-at="2017-07-18T00:34:11Z">
          <params>
            <param index="0">
              <value>
                <![CDATA[[command=sign_in&login=Anton&password=passWord4, command=ban_user&login=Petr&signIn=BAN, command=edit_access&login=Sema&access=U, command=sign_out&login=Anton]]]>
              </value>
            </param>
            <param index="1">
              <value>
                <![CDATA[[Welcom!, Profile is changed!, Access is changed!, Good Bye!]]]>
              </value>
            </param>
          </params>
          <exception class="java.lang.AssertionError">
            <message>
              <![CDATA[expected [Profile is changed!] but found [User already BAN!]]]>
            </message>
            <full-stacktrace>
              <![CDATA[java.lang.AssertionError: expected [Profile is changed!] but found [User already BAN!]
	at org.testng.Assert.fail(Assert.java:94)
	at org.testng.Assert.failNotEquals(Assert.java:513)
	at org.testng.Assert.assertEqualsImpl(Assert.java:135)
	at org.testng.Assert.assertEquals(Assert.java:116)
	at org.testng.Assert.assertEquals(Assert.java:190)
	at org.testng.Assert.assertEquals(Assert.java:200)
	at test.java.TstMultithreadServer.scenario1(TstMultithreadServer.java:45)
	at sun.reflect.NativeMethodAccessorImpl.invoke0(Native Method)
	at sun.reflect.NativeMethodAccessorImpl.invoke(Unknown Source)
	at sun.reflect.DelegatingMethodAccessorImpl.invoke(Unknown Source)
	at java.lang.reflect.Method.invoke(Unknown Source)
	at org.testng.internal.MethodInvocationHelper.invokeMethod(MethodInvocationHelper.java:100)
	at org.testng.internal.InvokeMethodRunnable.runOne(InvokeMethodRunnable.java:54)
	at org.testng.internal.InvokeMethodRunnable.run(InvokeMethodRunnable.java:44)
	at java.util.concurrent.Executors$RunnableAdapter.call(Unknown Source)
	at java.util.concurrent.FutureTask.run(Unknown Source)
	at java.util.concurrent.ThreadPoolExecutor.runWorker(Unknown Source)
	at java.util.concurrent.ThreadPoolExecutor$Worker.run(Unknown Source)
	at java.lang.Thread.run(Unknown Source)
]]>
            </full-stacktrace>
          </exception> <!-- java.lang.AssertionError -->
          <reporter-output>
          </reporter-output>
        </test-method> <!-- scenario1 -->
        <test-method status="FAIL" signature="scenario1(java.util.List, java.util.List)[pri:0, instance:test.java.TstMultithreadServer@31a5c39e]" name="scenario1" duration-ms="28" started-at="2017-07-18T00:34:11Z" data-provider="scenario1" finished-at="2017-07-18T00:34:11Z">
          <params>
            <param index="0">
              <value>
                <![CDATA[[command=sign_in&login=Anton&password=passWord4, command=ban_user&login=Petr&signIn=BAN, command=edit_access&login=Sema&access=U, command=sign_out&login=Anton]]]>
              </value>
            </param>
            <param index="1">
              <value>
                <![CDATA[[Welcom!, Profile is changed!, Access is changed!, Good Bye!]]]>
              </value>
            </param>
          </params>
          <exception class="java.lang.AssertionError">
            <message>
              <![CDATA[expected [Profile is changed!] but found [User already BAN!]]]>
            </message>
            <full-stacktrace>
              <![CDATA[java.lang.AssertionError: expected [Profile is changed!] but found [User already BAN!]
	at org.testng.Assert.fail(Assert.java:94)
	at org.testng.Assert.failNotEquals(Assert.java:513)
	at org.testng.Assert.assertEqualsImpl(Assert.java:135)
	at org.testng.Assert.assertEquals(Assert.java:116)
	at org.testng.Assert.assertEquals(Assert.java:190)
	at org.testng.Assert.assertEquals(Assert.java:200)
	at test.java.TstMultithreadServer.scenario1(TstMultithreadServer.java:45)
	at sun.reflect.NativeMethodAccessorImpl.invoke0(Native Method)
	at sun.reflect.NativeMethodAccessorImpl.invoke(Unknown Source)
	at sun.reflect.DelegatingMethodAccessorImpl.invoke(Unknown Source)
	at java.lang.reflect.Method.invoke(Unknown Source)
	at org.testng.internal.MethodInvocationHelper.invokeMethod(MethodInvocationHelper.java:100)
	at org.testng.internal.InvokeMethodRunnable.runOne(InvokeMethodRunnable.java:54)
	at org.testng.internal.InvokeMethodRunnable.run(InvokeMethodRunnable.java:44)
	at java.util.concurrent.Executors$RunnableAdapter.call(Unknown Source)
	at java.util.concurrent.FutureTask.run(Unknown Source)
	at java.util.concurrent.ThreadPoolExecutor.runWorker(Unknown Source)
	at java.util.concurrent.ThreadPoolExecutor$Worker.run(Unknown Source)
	at java.lang.Thread.run(Unknown Source)
]]>
            </full-stacktrace>
          </exception> <!-- java.lang.AssertionError -->
          <reporter-output>
          </reporter-output>
        </test-method> <!-- scenario1 -->
        <test-method status="FAIL" signature="scenario1(java.util.List, java.util.List)[pri:0, instance:test.java.TstMultithreadServer@31a5c39e]" name="scenario1" duration-ms="26" started-at="2017-07-18T00:34:11Z" data-provider="scenario1" finished-at="2017-07-18T00:34:11Z">
          <params>
            <param index="0">
              <value>
                <![CDATA[[command=sign_in&login=Anton&password=passWord4, command=ban_user&login=Petr&signIn=BAN, command=edit_access&login=Sema&access=U, command=sign_out&login=Anton]]]>
              </value>
            </param>
            <param index="1">
              <value>
                <![CDATA[[Welcom!, Profile is changed!, Access is changed!, Good Bye!]]]>
              </value>
            </param>
          </params>
          <exception class="java.lang.AssertionError">
            <message>
              <![CDATA[expected [Profile is changed!] but found [User already BAN!]]]>
            </message>
            <full-stacktrace>
              <![CDATA[java.lang.AssertionError: expected [Profile is changed!] but found [User already BAN!]
	at org.testng.Assert.fail(Assert.java:94)
	at org.testng.Assert.failNotEquals(Assert.java:513)
	at org.testng.Assert.assertEqualsImpl(Assert.java:135)
	at org.testng.Assert.assertEquals(Assert.java:116)
	at org.testng.Assert.assertEquals(Assert.java:190)
	at org.testng.Assert.assertEquals(Assert.java:200)
	at test.java.TstMultithreadServer.scenario1(TstMultithreadServer.java:45)
	at sun.reflect.NativeMethodAccessorImpl.invoke0(Native Method)
	at sun.reflect.NativeMethodAccessorImpl.invoke(Unknown Source)
	at sun.reflect.DelegatingMethodAccessorImpl.invoke(Unknown Source)
	at java.lang.reflect.Method.invoke(Unknown Source)
	at org.testng.internal.MethodInvocationHelper.invokeMethod(MethodInvocationHelper.java:100)
	at org.testng.internal.InvokeMethodRunnable.runOne(InvokeMethodRunnable.java:54)
	at org.testng.internal.InvokeMethodRunnable.run(InvokeMethodRunnable.java:44)
	at java.util.concurrent.Executors$RunnableAdapter.call(Unknown Source)
	at java.util.concurrent.FutureTask.run(Unknown Source)
	at java.util.concurrent.ThreadPoolExecutor.runWorker(Unknown Source)
	at java.util.concurrent.ThreadPoolExecutor$Worker.run(Unknown Source)
	at java.lang.Thread.run(Unknown Source)
]]>
            </full-stacktrace>
          </exception> <!-- java.lang.AssertionError -->
          <reporter-output>
          </reporter-output>
        </test-method> <!-- scenario1 -->
        <test-method status="FAIL" signature="scenario1(java.util.List, java.util.List)[pri:0, instance:test.java.TstMultithreadServer@31a5c39e]" name="scenario1" duration-ms="28" started-at="2017-07-18T00:34:11Z" data-provider="scenario1" finished-at="2017-07-18T00:34:11Z">
          <params>
            <param index="0">
              <value>
                <![CDATA[[command=sign_in&login=Anton&password=passWord4, command=ban_user&login=Petr&signIn=BAN, command=edit_access&login=Sema&access=U, command=sign_out&login=Anton]]]>
              </value>
            </param>
            <param index="1">
              <value>
                <![CDATA[[Welcom!, Profile is changed!, Access is changed!, Good Bye!]]]>
              </value>
            </param>
          </params>
          <exception class="java.lang.AssertionError">
            <message>
              <![CDATA[expected [Profile is changed!] but found [User already BAN!]]]>
            </message>
            <full-stacktrace>
              <![CDATA[java.lang.AssertionError: expected [Profile is changed!] but found [User already BAN!]
	at org.testng.Assert.fail(Assert.java:94)
	at org.testng.Assert.failNotEquals(Assert.java:513)
	at org.testng.Assert.assertEqualsImpl(Assert.java:135)
	at org.testng.Assert.assertEquals(Assert.java:116)
	at org.testng.Assert.assertEquals(Assert.java:190)
	at org.testng.Assert.assertEquals(Assert.java:200)
	at test.java.TstMultithreadServer.scenario1(TstMultithreadServer.java:45)
	at sun.reflect.NativeMethodAccessorImpl.invoke0(Native Method)
	at sun.reflect.NativeMethodAccessorImpl.invoke(Unknown Source)
	at sun.reflect.DelegatingMethodAccessorImpl.invoke(Unknown Source)
	at java.lang.reflect.Method.invoke(Unknown Source)
	at org.testng.internal.MethodInvocationHelper.invokeMethod(MethodInvocationHelper.java:100)
	at org.testng.internal.InvokeMethodRunnable.runOne(InvokeMethodRunnable.java:54)
	at org.testng.internal.InvokeMethodRunnable.run(InvokeMethodRunnable.java:44)
	at java.util.concurrent.Executors$RunnableAdapter.call(Unknown Source)
	at java.util.concurrent.FutureTask.run(Unknown Source)
	at java.util.concurrent.ThreadPoolExecutor.runWorker(Unknown Source)
	at java.util.concurrent.ThreadPoolExecutor$Worker.run(Unknown Source)
	at java.lang.Thread.run(Unknown Source)
]]>
            </full-stacktrace>
          </exception> <!-- java.lang.AssertionError -->
          <reporter-output>
          </reporter-output>
        </test-method> <!-- scenario1 -->
        <test-method status="PASS" signature="afterTest()[pri:0, instance:test.java.TstMultithreadServer@31a5c39e]" name="afterTest" is-config="true" duration-ms="199" started-at="2017-07-18T00:34:11Z" finished-at="2017-07-18T00:34:11Z">
          <reporter-output>
          </reporter-output>
        </test-method> <!-- afterTest -->
      </class> <!-- test.java.TstMultithreadServer -->
    </test> <!-- Default test -->
  </suite> <!-- Default suite -->
</testng-results>
